Failure # 1 (occurred at 2023-07-26_18-03-23)
[36mray::A2C.restore()[39m (pid=7612, ip=127.0.0.1, actor_id=4beccc75cf6b9ea3f8ab502701000000, repr=A2C)
  File "/Users/akest/miniforge3/envs/conda_env/lib/python3.9/site-packages/ray/tune/trainable/trainable.py", line 876, in restore
    raise ValueError(
ValueError: Could not recover from checkpoint as it does not exist on local disk and was not available on cloud storage or another Ray node. Got checkpoint path: None and IP None
