Failure # 1 (occurred at 2023-07-14_15-38-38)
[36mray::PPO.restore()[39m (pid=54130, ip=127.0.0.1, actor_id=24b8f4b753a17707a9b7338301000000, repr=PPO)
  File "/Users/akest/miniforge3/envs/conda_env/lib/python3.9/site-packages/ray/tune/trainable/trainable.py", line 876, in restore
    raise ValueError(
ValueError: Could not recover from checkpoint as it does not exist on local disk and was not available on cloud storage or another Ray node. Got checkpoint path: None and IP None
